<?xml version="1.0" encoding="utf-8"?>
<!-- =================================================================================== -->
<!-- |    This document was autogenerated by xacro from dogbot.xacro                   | -->
<!-- |    EDITING THIS FILE BY HAND IS NOT RECOMMENDED                                 | -->
<!-- =================================================================================== -->
<robot name="dogbot" xmlns:xacro="http://ros.org/wiki/xacro">
  <!-- ===================================================================================
     |    DogBot v4 URDF                                                               |
     |    2019 React Robotics Ltd
     |
     |    Licence: CC-BY, https://creativecommons.org/licenses/by/4.0/legalcode
     |    Author:  Nic Greenway, nic@reactrobotics.com
     |
     |    Note: some details of mass and inertia in this file are estimates, 
     |    as DogBot design is still undergoing refinements, and values will vary
     |    with individual DogBot specification (e.g. battery configuration, on-board
     |    processor, etc.)
     =================================================================================== -->
  <material name="blue">
    <color rgba="0 0 0.8 1"/>
  </material>
  <material name="black">
    <color rgba="0 0 0 1"/>
  </material>
  <material name="white">
    <color rgba="1 1 1 1"/>
  </material>
  <material name="dogbotred">
    <color rgba="1 0 0 1"/>
  </material>
  <material name="dogbotgray">
    <color rgba="0.7 0.7 0.7 1"/>
  </material>
  <!-- start the robot links -->
  <link name="base_link">
  </link>
  <link name="body">
    <visual>
      <origin rpy="-1.57079632679 0 0" xyz="0 0 0"/>
      <geometry>
        <mesh filename="package://dogbot_description/meshes/body.dae" scale="1.0 1.0 1.0"/>
      </geometry>
    </visual>
    <collision>
      <origin rpy="0 0 0" xyz="0 0 0"/>
      <geometry>
        <box size="0.177 0.433 0.105"/>
      </geometry>
    </collision>
    <collision>
      <origin rpy="1.57079632679 0 0" xyz="0.0885 0 0"/>
      <geometry>
        <cylinder length="0.433" radius="0.0525"/>
      </geometry>
    </collision>
    <collision>
      <origin rpy="1.57079632679 0 0" xyz="-0.0885 0 0"/>
      <geometry>
        <cylinder length="0.433" radius="0.0525"/>
      </geometry>
    </collision>
    <collision>
      <origin rpy="0 0 0" xyz="0 0.2825 0"/>
      <geometry>
        <box size="0.035 0.132 0.105"/>
      </geometry>
    </collision>
    <collision>
      <origin rpy="0 0 0" xyz="0 -0.2825 0"/>
      <geometry>
        <box size="0.035 0.132 0.105"/>
      </geometry>
    </collision>
    <collision>
      <origin rpy="0 0 0" xyz="0 0.3975 0"/>
      <geometry>
        <box size="0.177 0.08 0.105"/>
      </geometry>
    </collision>
    <collision>
      <origin rpy="1.57079632679 0 0" xyz="0.0885 0.3975 0"/>
      <geometry>
        <cylinder length="0.08" radius="0.0525"/>
      </geometry>
    </collision>
    <collision>
      <origin rpy="1.57079632679 0 0" xyz="-0.0885 0.3975 0"/>
      <geometry>
        <cylinder length="0.08" radius="0.0525"/>
      </geometry>
    </collision>
    <collision>
      <origin rpy="0 0 0" xyz="0 -0.3975 0"/>
      <geometry>
        <box size="0.177 0.08 0.105"/>
      </geometry>
    </collision>
    <collision>
      <origin rpy="1.57079632679 0 0" xyz="0.0885 -0.3975 0"/>
      <geometry>
        <cylinder length="0.08" radius="0.0525"/>
      </geometry>
    </collision>
    <collision>
      <origin rpy="1.57079632679 0 0" xyz="-0.0885 -0.3975 0"/>
      <geometry>
        <cylinder length="0.08" radius="0.0525"/>
      </geometry>
    </collision>
    <inertial>
      <mass value="9.3"/>
      <origin rpy="0 0 0" xyz="0 0 0"/>
      <inertia ixx="0.41" ixy="0" ixz="0" iyy="0.091" iyz="0" izz="0.482"/>
    </inertial>
  </link>
  <joint name="base_joint" type="fixed">
    <axis rpy="0 0 0" xyz="0 0 0"/>
    <parent link="base_link"/>
    <child link="body"/>
  </joint>
  <link name="bodytext">
    <visual>
      <origin rpy="-1.57079632679 0 0" xyz="0 0 0"/>
      <geometry>
        <mesh filename="package://dogbot_description/meshes/bodyTEXT.dae" scale="1.0 1.0 1.0"/>
      </geometry>
    </visual>
    <inertial>
      <mass value="0.001"/>
      <origin rpy="0 0 0" xyz="0 0 0"/>
      <inertia ixx="1.66666666667e-10" ixy="0.0" ixz="0.0" iyy="1.66666666667e-10" iyz="0.0" izz="1.66666666667e-10"/>
    </inertial>
  </link>
  <joint name="bodytext_joint" type="fixed">
    <parent link="body"/>
    <child link="bodytext"/>
  </joint>
  <gazebo reference="body">
    <mu1 value="200.0"/>
    <mu2 value="100.0"/>
    <kp value="1000000"/>
    <kd value="1.0"/>
  </gazebo>
  <link name="back_left_hip">
    <visual>
      <origin rpy="-1.57079632679 -3.14159265359 0" xyz="0 0 0"/>
      <geometry>
        <mesh filename="package://dogbot_description/meshes/hip.dae" scale="1.0 1.0 1.0"/>
      </geometry>
    </visual>
    <collision>
      <origin rpy="0 1.57079632679 0" xyz="-0.02 0 0"/>
      <geometry>
        <cylinder length="0.08" radius="0.0525"/>
      </geometry>
    </collision>
    <inertial>
      <mass value="0.836"/>
      <origin rpy="0 0 0" xyz="-0.0074 0 0"/>
      <inertia ixx="0.00213" ixy="0" ixz="0" iyy="0.00147" iyz="0" izz="0.00172"/>
    </inertial>
  </link>
  <!-- roll joint connects the hip to the body -->
  <joint name="back_left_roll_joint" type="revolute">
    <axis rpy="0 0 0" xyz="0 -1 0"/>
    <parent link="body"/>
    <child link="back_left_hip"/>
    <origin rpy="0 0 0" xyz="-0.088 -0.2795 0"/>
    <limit effort="60" lower="-1.7453" upper="1.7453" velocity="6.0"/>
  </joint>
  <link name="back_left_upperleg">
    <visual>
      <origin rpy="-1.57079632679 0 -3.14159265359" xyz="0 0 0"/>
      <geometry>
        <mesh filename="package://dogbot_description/meshes/LegUpper_withCover.dae" scale="1.0 1.0 1.0"/>
      </geometry>
    </visual>
    <collision>
      <origin rpy="0 1.57079632679 0" xyz="-0.03 0 0"/>
      <geometry>
        <cylinder length="0.13" radius="0.0525"/>
      </geometry>
    </collision>
    <collision>
      <origin rpy="0 0 0" xyz="0 0 -0.135"/>
      <geometry>
        <cylinder length="0.27" radius="0.033"/>
      </geometry>
    </collision>
    <collision>
      <origin rpy="0 0 0" xyz="0 0 -0.135"/>
      <geometry>
        <box size="0.025 0.084 0.27"/>
      </geometry>
    </collision>
    <collision>
      <origin rpy="0 0 0" xyz="-0.046 0 -0.126"/>
      <geometry>
        <box size="0.026 0.074 0.138"/>
      </geometry>
    </collision>
    <collision>
      <origin rpy="0 1.57079632679 0" xyz="-0.03 0 -0.315"/>
      <geometry>
        <cylinder length="0.018" radius="0.017"/>
      </geometry>
    </collision>
    <collision>
      <origin rpy="0 1.57079632679 0" xyz="0.036 0 -0.315"/>
      <geometry>
        <cylinder length="0.013" radius="0.017"/>
      </geometry>
    </collision>
    <inertial>
      <mass value="1.851"/>
      <origin rpy="0 0 0" xyz="-0.0418 0 -0.0517"/>
      <inertia ixx="0.0238" ixy="0" ixz="0" iyy="0.0252" iyz="0" izz="0.0044"/>
    </inertial>
  </link>
  <!-- pitch joint connects hip to upper leg -->
  <joint name="back_left_pitch_joint" type="revolute">
    <axis rpy="0 0 0" xyz="-1 0 0"/>
    <parent link="back_left_hip"/>
    <child link="back_left_upperleg"/>
    <origin rpy="0 0 0" xyz="-0.09875 0 0"/>
    <limit effort="60" lower="-1.57079632679" upper="3.14159265359" velocity="6.0"/>
  </joint>
  <link name="back_left_lowerleg">
    <visual>
      <origin rpy="-1.57079632679 0 0" xyz="0 0 0"/>
      <geometry>
        <mesh filename="package://dogbot_description/meshes/LegLower_nofoot.dae" scale="1.0 1.0 1.0"/>
      </geometry>
    </visual>
    <collision>
      <origin rpy="0 1.57079632679 0" xyz="0 0 0"/>
      <geometry>
        <cylinder length="0.033" radius="0.042"/>
      </geometry>
    </collision>
    <collision>
      <origin rpy="0 0 0" xyz="0.024 -0.0375 -0.0055"/>
      <geometry>
        <box size="0.02 0.017 0.065"/>
      </geometry>
    </collision>
    <collision>
      <origin rpy="0 0 0" xyz="-0.024 -0.0375 -0.0055"/>
      <geometry>
        <box size="0.02 0.017 0.065"/>
      </geometry>
    </collision>
    <collision>
      <origin rpy="0 0.04996 0" xyz="0.01575 -0.0375 -0.145"/>
      <geometry>
        <cylinder length="0.29" radius="0.006"/>
      </geometry>
    </collision>
    <collision>
      <origin rpy="0 -0.04996 0" xyz="-0.01575 -0.0375 -0.145"/>
      <geometry>
        <cylinder length="0.29" radius="0.006"/>
      </geometry>
    </collision>
    <inertial>
      <mass value="0.302"/>
      <origin rpy="0 0 0" xyz="0 -0.029 -0.1439"/>
      <inertia ixx="0.00527" ixy="0" ixz="0" iyy="0.00509" iyz="0" izz="0.0008"/>
    </inertial>
  </link>
  <gazebo reference="back_left_lowerleg">
    <mu1 value="2000.0"/>
    <mu2 value="1000.0"/>
    <kp value="1000000"/>
    <kd value="1.0"/>
    <selfCollide value="true"/>
  </gazebo>
  <joint name="back_left_knee_joint" type="revolute">
    <axis rpy="-6.28318530718 0 0" xyz="-1 0 0"/>
    <parent link="back_left_upperleg"/>
    <child link="back_left_lowerleg"/>
    <origin rpy="0 0 0" xyz="0 0 -0.315"/>
    <limit effort="60" lower="-2.61795" upper="0.02" velocity="6.0"/>
  </joint>
  <link name="back_left_foot">
    <visual>
      <origin rpy="-1.57079632679 0 0" xyz="0 0 0"/>
      <geometry>
        <mesh filename="package://dogbot_description/meshes/foot.dae" scale="1.0 1.0 1.0"/>
      </geometry>
    </visual>
    <collision>
      <origin rpy="0 0 0" xyz="0 -0.035 -0.3"/>
      <geometry>
        <sphere radius="0.028"/>
      </geometry>
    </collision>
    <inertial>
      <mass value="0.001"/>
      <origin rpy="0 0 0" xyz="0 0 0"/>
      <inertia ixx="1.66666666667e-10" ixy="0.0" ixz="0.0" iyy="1.66666666667e-10" iyz="0.0" izz="1.66666666667e-10"/>
    </inertial>
  </link>
  <joint name="back_left_foot_joint" type="fixed">
    <axis rpy="0 0 0" xyz="0 1 0"/>
    <parent link="back_left_lowerleg"/>
    <child link="back_left_foot"/>
    <origin rpy="0 0 0" xyz="0 0 0"/>
  </joint>
  <gazebo reference="back_left_foot">
    <mu1 value="2000.0"/>
    <mu2 value="1000.0"/>
    <kp value="1000000"/>
    <kd value="1.0"/>
  </gazebo>
  <transmission name="back_left_roll_transmition">
    <type>transmission_interface/SimpleTransmission</type>
    <joint name="back_left_roll_joint">
      <hardwareInterface>hardware_interface/EffortJointInterface</hardwareInterface>
    </joint>
    <actuator name="back_left_roll_motor">
      <hardwareInterface>hardware_interface/EffortJointInterface</hardwareInterface>
      <mechanicalReduction>1</mechanicalReduction>
    </actuator>
  </transmission>
  <transmission name="back_left_pitch_transmition">
    <type>transmission_interface/SimpleTransmission</type>
    <joint name="back_left_pitch_joint">
      <hardwareInterface>hardware_interface/EffortJointInterface</hardwareInterface>
    </joint>
    <actuator name="back_left_pitch_motor">
      <hardwareInterface>hardware_interface/EffortJointInterface</hardwareInterface>
      <mechanicalReduction>1</mechanicalReduction>
    </actuator>
  </transmission>
  <transmission name="back_left_knee_transmition">
    <type>transmission_interface/SimpleTransmission</type>
    <joint name="back_left_knee_joint">
      <hardwareInterface>hardware_interface/EffortJointInterface</hardwareInterface>
    </joint>
    <actuator name="back_left_knee_motor">
      <hardwareInterface>hardware_interface/EffortJointInterface</hardwareInterface>
      <mechanicalReduction>1</mechanicalReduction>
    </actuator>
  </transmission>
  <link name="back_right_hip">
    <visual>
      <origin rpy="-1.57079632679 0.0 0" xyz="0 0 0"/>
      <geometry>
        <mesh filename="package://dogbot_description/meshes/hip.dae" scale="1.0 1.0 1.0"/>
      </geometry>
    </visual>
    <collision>
      <origin rpy="0 1.57079632679 0" xyz="0.02 0 0"/>
      <geometry>
        <cylinder length="0.08" radius="0.0525"/>
      </geometry>
    </collision>
    <inertial>
      <mass value="0.836"/>
      <origin rpy="0 0 0" xyz="0.0074 0 0"/>
      <inertia ixx="0.00213" ixy="0" ixz="0" iyy="0.00147" iyz="0" izz="0.00172"/>
    </inertial>
  </link>
  <!-- roll joint connects the hip to the body -->
  <joint name="back_right_roll_joint" type="revolute">
    <axis rpy="0 0 0" xyz="0 -1 0"/>
    <parent link="body"/>
    <child link="back_right_hip"/>
    <origin rpy="0 0 0" xyz="0.088 -0.2795 0"/>
    <limit effort="60" lower="-1.7453" upper="1.7453" velocity="6.0"/>
  </joint>
  <link name="back_right_upperleg">
    <visual>
      <origin rpy="-1.57079632679 0 0.0" xyz="0 0 0"/>
      <geometry>
        <mesh filename="package://dogbot_description/meshes/LegUpper_withCover.dae" scale="1.0 1.0 1.0"/>
      </geometry>
    </visual>
    <collision>
      <origin rpy="0 1.57079632679 0" xyz="0.03 0 0"/>
      <geometry>
        <cylinder length="0.13" radius="0.0525"/>
      </geometry>
    </collision>
    <collision>
      <origin rpy="0 0 0" xyz="0 0 -0.135"/>
      <geometry>
        <cylinder length="0.27" radius="0.033"/>
      </geometry>
    </collision>
    <collision>
      <origin rpy="0 0 0" xyz="0 0 -0.135"/>
      <geometry>
        <box size="0.025 0.084 0.27"/>
      </geometry>
    </collision>
    <collision>
      <origin rpy="0 0 0" xyz="0.046 0 -0.126"/>
      <geometry>
        <box size="0.026 0.074 0.138"/>
      </geometry>
    </collision>
    <collision>
      <origin rpy="0 1.57079632679 0" xyz="0.03 0 -0.315"/>
      <geometry>
        <cylinder length="0.018" radius="0.017"/>
      </geometry>
    </collision>
    <collision>
      <origin rpy="0 1.57079632679 0" xyz="-0.036 0 -0.315"/>
      <geometry>
        <cylinder length="0.013" radius="0.017"/>
      </geometry>
    </collision>
    <inertial>
      <mass value="1.851"/>
      <origin rpy="0 0 0" xyz="0.0418 0 -0.0517"/>
      <inertia ixx="0.0238" ixy="0" ixz="0" iyy="0.0252" iyz="0" izz="0.0044"/>
    </inertial>
  </link>
  <!-- pitch joint connects hip to upper leg -->
  <joint name="back_right_pitch_joint" type="revolute">
    <axis rpy="0 0 0" xyz="1 0 0"/>
    <parent link="back_right_hip"/>
    <child link="back_right_upperleg"/>
    <origin rpy="0 0 0" xyz="0.09875 0 0"/>
    <limit effort="60" lower="-3.14159265359" upper="1.57079632679" velocity="6.0"/>
  </joint>
  <link name="back_right_lowerleg">
    <visual>
      <origin rpy="-1.57079632679 0 0" xyz="0 0 0"/>
      <geometry>
        <mesh filename="package://dogbot_description/meshes/LegLower_nofoot.dae" scale="1.0 1.0 1.0"/>
      </geometry>
    </visual>
    <collision>
      <origin rpy="0 1.57079632679 0" xyz="0 0 0"/>
      <geometry>
        <cylinder length="0.033" radius="0.042"/>
      </geometry>
    </collision>
    <collision>
      <origin rpy="0 0 0" xyz="0.024 -0.0375 -0.0055"/>
      <geometry>
        <box size="0.02 0.017 0.065"/>
      </geometry>
    </collision>
    <collision>
      <origin rpy="0 0 0" xyz="-0.024 -0.0375 -0.0055"/>
      <geometry>
        <box size="0.02 0.017 0.065"/>
      </geometry>
    </collision>
    <collision>
      <origin rpy="0 0.04996 0" xyz="0.01575 -0.0375 -0.145"/>
      <geometry>
        <cylinder length="0.29" radius="0.006"/>
      </geometry>
    </collision>
    <collision>
      <origin rpy="0 -0.04996 0" xyz="-0.01575 -0.0375 -0.145"/>
      <geometry>
        <cylinder length="0.29" radius="0.006"/>
      </geometry>
    </collision>
    <inertial>
      <mass value="0.302"/>
      <origin rpy="0 0 0" xyz="0 -0.029 -0.1439"/>
      <inertia ixx="0.00527" ixy="0" ixz="0" iyy="0.00509" iyz="0" izz="0.0008"/>
    </inertial>
  </link>
  <gazebo reference="back_right_lowerleg">
    <mu1 value="2000.0"/>
    <mu2 value="1000.0"/>
    <kp value="1000000"/>
    <kd value="1.0"/>
    <selfCollide value="true"/>
  </gazebo>
  <joint name="back_right_knee_joint" type="revolute">
    <axis rpy="-6.28318530718 0 0" xyz="1 0 0"/>
    <parent link="back_right_upperleg"/>
    <child link="back_right_lowerleg"/>
    <origin rpy="0 0 0" xyz="0 0 -0.315"/>
    <limit effort="60" lower="-0.02" upper="2.61795" velocity="6.0"/>
  </joint>
  <link name="back_right_foot">
    <visual>
      <origin rpy="-1.57079632679 0 0" xyz="0 0 0"/>
      <geometry>
        <mesh filename="package://dogbot_description/meshes/foot.dae" scale="1.0 1.0 1.0"/>
      </geometry>
    </visual>
    <collision>
      <origin rpy="0 0 0" xyz="0 -0.035 -0.3"/>
      <geometry>
        <sphere radius="0.028"/>
      </geometry>
    </collision>
    <inertial>
      <mass value="0.001"/>
      <origin rpy="0 0 0" xyz="0 0 0"/>
      <inertia ixx="1.66666666667e-10" ixy="0.0" ixz="0.0" iyy="1.66666666667e-10" iyz="0.0" izz="1.66666666667e-10"/>
    </inertial>
  </link>
  <joint name="back_right_foot_joint" type="fixed">
    <axis rpy="0 0 0" xyz="0 1 0"/>
    <parent link="back_right_lowerleg"/>
    <child link="back_right_foot"/>
    <origin rpy="0 0 0" xyz="0 0 0"/>
  </joint>
  <gazebo reference="back_right_foot">
    <mu1 value="2000.0"/>
    <mu2 value="1000.0"/>
    <kp value="1000000"/>
    <kd value="1.0"/>
  </gazebo>
  <transmission name="back_right_roll_transmition">
    <type>transmission_interface/SimpleTransmission</type>
    <joint name="back_right_roll_joint">
      <hardwareInterface>hardware_interface/EffortJointInterface</hardwareInterface>
    </joint>
    <actuator name="back_right_roll_motor">
      <hardwareInterface>hardware_interface/EffortJointInterface</hardwareInterface>
      <mechanicalReduction>1</mechanicalReduction>
    </actuator>
  </transmission>
  <transmission name="back_right_pitch_transmition">
    <type>transmission_interface/SimpleTransmission</type>
    <joint name="back_right_pitch_joint">
      <hardwareInterface>hardware_interface/EffortJointInterface</hardwareInterface>
    </joint>
    <actuator name="back_right_pitch_motor">
      <hardwareInterface>hardware_interface/EffortJointInterface</hardwareInterface>
      <mechanicalReduction>1</mechanicalReduction>
    </actuator>
  </transmission>
  <transmission name="back_right_knee_transmition">
    <type>transmission_interface/SimpleTransmission</type>
    <joint name="back_right_knee_joint">
      <hardwareInterface>hardware_interface/EffortJointInterface</hardwareInterface>
    </joint>
    <actuator name="back_right_knee_motor">
      <hardwareInterface>hardware_interface/EffortJointInterface</hardwareInterface>
      <mechanicalReduction>1</mechanicalReduction>
    </actuator>
  </transmission>
  <link name="front_left_hip">
    <visual>
      <origin rpy="-1.57079632679 -3.14159265359 0" xyz="0 0 0"/>
      <geometry>
        <mesh filename="package://dogbot_description/meshes/hip.dae" scale="1.0 1.0 1.0"/>
      </geometry>
    </visual>
    <collision>
      <origin rpy="0 1.57079632679 0" xyz="-0.02 0 0"/>
      <geometry>
        <cylinder length="0.08" radius="0.0525"/>
      </geometry>
    </collision>
    <inertial>
      <mass value="0.836"/>
      <origin rpy="0 0 0" xyz="-0.0074 0 0"/>
      <inertia ixx="0.00213" ixy="0" ixz="0" iyy="0.00147" iyz="0" izz="0.00172"/>
    </inertial>
  </link>
  <!-- roll joint connects the hip to the body -->
  <joint name="front_left_roll_joint" type="revolute">
    <axis rpy="0 0 0" xyz="0 1 0"/>
    <parent link="body"/>
    <child link="front_left_hip"/>
    <origin rpy="0 0 0" xyz="-0.088 0.2795 0"/>
    <limit effort="60" lower="-1.7453" upper="1.7453" velocity="6.0"/>
  </joint>
  <link name="front_left_upperleg">
    <visual>
      <origin rpy="-1.57079632679 0 -3.14159265359" xyz="0 0 0"/>
      <geometry>
        <mesh filename="package://dogbot_description/meshes/LegUpper_withCover.dae" scale="1.0 1.0 1.0"/>
      </geometry>
    </visual>
    <collision>
      <origin rpy="0 1.57079632679 0" xyz="-0.03 0 0"/>
      <geometry>
        <cylinder length="0.13" radius="0.0525"/>
      </geometry>
    </collision>
    <collision>
      <origin rpy="0 0 0" xyz="0 0 -0.135"/>
      <geometry>
        <cylinder length="0.27" radius="0.033"/>
      </geometry>
    </collision>
    <collision>
      <origin rpy="0 0 0" xyz="0 0 -0.135"/>
      <geometry>
        <box size="0.025 0.084 0.27"/>
      </geometry>
    </collision>
    <collision>
      <origin rpy="0 0 0" xyz="-0.046 0 -0.126"/>
      <geometry>
        <box size="0.026 0.074 0.138"/>
      </geometry>
    </collision>
    <collision>
      <origin rpy="0 1.57079632679 0" xyz="-0.03 0 -0.315"/>
      <geometry>
        <cylinder length="0.018" radius="0.017"/>
      </geometry>
    </collision>
    <collision>
      <origin rpy="0 1.57079632679 0" xyz="0.036 0 -0.315"/>
      <geometry>
        <cylinder length="0.013" radius="0.017"/>
      </geometry>
    </collision>
    <inertial>
      <mass value="1.851"/>
      <origin rpy="0 0 0" xyz="-0.0418 0 -0.0517"/>
      <inertia ixx="0.0238" ixy="0" ixz="0" iyy="0.0252" iyz="0" izz="0.0044"/>
    </inertial>
  </link>
  <!-- pitch joint connects hip to upper leg -->
  <joint name="front_left_pitch_joint" type="revolute">
    <axis rpy="0 0 0" xyz="-1 0 0"/>
    <parent link="front_left_hip"/>
    <child link="front_left_upperleg"/>
    <origin rpy="0 0 0" xyz="-0.09875 0 0"/>
    <limit effort="60" lower="-1.57079632679" upper="3.14159265359" velocity="6.0"/>
  </joint>
  <link name="front_left_lowerleg">
    <visual>
      <origin rpy="-1.57079632679 0 0" xyz="0 0 0"/>
      <geometry>
        <mesh filename="package://dogbot_description/meshes/LegLower_nofoot.dae" scale="1.0 1.0 1.0"/>
      </geometry>
    </visual>
    <collision>
      <origin rpy="0 1.57079632679 0" xyz="0 0 0"/>
      <geometry>
        <cylinder length="0.033" radius="0.042"/>
      </geometry>
    </collision>
    <collision>
      <origin rpy="0 0 0" xyz="0.024 -0.0375 -0.0055"/>
      <geometry>
        <box size="0.02 0.017 0.065"/>
      </geometry>
    </collision>
    <collision>
      <origin rpy="0 0 0" xyz="-0.024 -0.0375 -0.0055"/>
      <geometry>
        <box size="0.02 0.017 0.065"/>
      </geometry>
    </collision>
    <collision>
      <origin rpy="0 0.04996 0" xyz="0.01575 -0.0375 -0.145"/>
      <geometry>
        <cylinder length="0.29" radius="0.006"/>
      </geometry>
    </collision>
    <collision>
      <origin rpy="0 -0.04996 0" xyz="-0.01575 -0.0375 -0.145"/>
      <geometry>
        <cylinder length="0.29" radius="0.006"/>
      </geometry>
    </collision>
    <inertial>
      <mass value="0.302"/>
      <origin rpy="0 0 0" xyz="0 -0.029 -0.1439"/>
      <inertia ixx="0.00527" ixy="0" ixz="0" iyy="0.00509" iyz="0" izz="0.0008"/>
    </inertial>
  </link>
  <gazebo reference="front_left_lowerleg">
    <mu1 value="2000.0"/>
    <mu2 value="1000.0"/>
    <kp value="1000000"/>
    <kd value="1.0"/>
    <selfCollide value="true"/>
  </gazebo>
  <joint name="front_left_knee_joint" type="revolute">
    <axis rpy="-6.28318530718 0 0" xyz="-1 0 0"/>
    <parent link="front_left_upperleg"/>
    <child link="front_left_lowerleg"/>
    <origin rpy="0 0 0" xyz="0 0 -0.315"/>
    <limit effort="60" lower="-2.61795" upper="0.02" velocity="6.0"/>
  </joint>
  <link name="front_left_foot">
    <visual>
      <origin rpy="-1.57079632679 0 0" xyz="0 0 0"/>
      <geometry>
        <mesh filename="package://dogbot_description/meshes/foot.dae" scale="1.0 1.0 1.0"/>
      </geometry>
    </visual>
    <collision>
      <origin rpy="0 0 0" xyz="0 -0.035 -0.3"/>
      <geometry>
        <sphere radius="0.028"/>
      </geometry>
    </collision>
    <inertial>
      <mass value="0.001"/>
      <origin rpy="0 0 0" xyz="0 0 0"/>
      <inertia ixx="1.66666666667e-10" ixy="0.0" ixz="0.0" iyy="1.66666666667e-10" iyz="0.0" izz="1.66666666667e-10"/>
    </inertial>
  </link>
  <joint name="front_left_foot_joint" type="fixed">
    <axis rpy="0 0 0" xyz="0 1 0"/>
    <parent link="front_left_lowerleg"/>
    <child link="front_left_foot"/>
    <origin rpy="0 0 0" xyz="0 0 0"/>
  </joint>
  <gazebo reference="front_left_foot">
    <mu1 value="2000.0"/>
    <mu2 value="1000.0"/>
    <kp value="1000000"/>
    <kd value="1.0"/>
  </gazebo>
  <transmission name="front_left_roll_transmition">
    <type>transmission_interface/SimpleTransmission</type>
    <joint name="front_left_roll_joint">
      <hardwareInterface>hardware_interface/EffortJointInterface</hardwareInterface>
    </joint>
    <actuator name="front_left_roll_motor">
      <hardwareInterface>hardware_interface/EffortJointInterface</hardwareInterface>
      <mechanicalReduction>1</mechanicalReduction>
    </actuator>
  </transmission>
  <transmission name="front_left_pitch_transmition">
    <type>transmission_interface/SimpleTransmission</type>
    <joint name="front_left_pitch_joint">
      <hardwareInterface>hardware_interface/EffortJointInterface</hardwareInterface>
    </joint>
    <actuator name="front_left_pitch_motor">
      <hardwareInterface>hardware_interface/EffortJointInterface</hardwareInterface>
      <mechanicalReduction>1</mechanicalReduction>
    </actuator>
  </transmission>
  <transmission name="front_left_knee_transmition">
    <type>transmission_interface/SimpleTransmission</type>
    <joint name="front_left_knee_joint">
      <hardwareInterface>hardware_interface/EffortJointInterface</hardwareInterface>
    </joint>
    <actuator name="front_left_knee_motor">
      <hardwareInterface>hardware_interface/EffortJointInterface</hardwareInterface>
      <mechanicalReduction>1</mechanicalReduction>
    </actuator>
  </transmission>
  <link name="front_right_hip">
    <visual>
      <origin rpy="-1.57079632679 0.0 0" xyz="0 0 0"/>
      <geometry>
        <mesh filename="package://dogbot_description/meshes/hip.dae" scale="1.0 1.0 1.0"/>
      </geometry>
    </visual>
    <collision>
      <origin rpy="0 1.57079632679 0" xyz="0.02 0 0"/>
      <geometry>
        <cylinder length="0.08" radius="0.0525"/>
      </geometry>
    </collision>
    <inertial>
      <mass value="0.836"/>
      <origin rpy="0 0 0" xyz="0.0074 0 0"/>
      <inertia ixx="0.00213" ixy="0" ixz="0" iyy="0.00147" iyz="0" izz="0.00172"/>
    </inertial>
  </link>
  <!-- roll joint connects the hip to the body -->
  <joint name="front_right_roll_joint" type="revolute">
    <axis rpy="0 0 0" xyz="0 1 0"/>
    <parent link="body"/>
    <child link="front_right_hip"/>
    <origin rpy="0 0 0" xyz="0.088 0.2795 0"/>
    <limit effort="60" lower="-1.7453" upper="1.7453" velocity="6.0"/>
  </joint>
  <link name="front_right_upperleg">
    <visual>
      <origin rpy="-1.57079632679 0 0.0" xyz="0 0 0"/>
      <geometry>
        <mesh filename="package://dogbot_description/meshes/LegUpper_withCover.dae" scale="1.0 1.0 1.0"/>
      </geometry>
    </visual>
    <collision>
      <origin rpy="0 1.57079632679 0" xyz="0.03 0 0"/>
      <geometry>
        <cylinder length="0.13" radius="0.0525"/>
      </geometry>
    </collision>
    <collision>
      <origin rpy="0 0 0" xyz="0 0 -0.135"/>
      <geometry>
        <cylinder length="0.27" radius="0.033"/>
      </geometry>
    </collision>
    <collision>
      <origin rpy="0 0 0" xyz="0 0 -0.135"/>
      <geometry>
        <box size="0.025 0.084 0.27"/>
      </geometry>
    </collision>
    <collision>
      <origin rpy="0 0 0" xyz="0.046 0 -0.126"/>
      <geometry>
        <box size="0.026 0.074 0.138"/>
      </geometry>
    </collision>
    <collision>
      <origin rpy="0 1.57079632679 0" xyz="0.03 0 -0.315"/>
      <geometry>
        <cylinder length="0.018" radius="0.017"/>
      </geometry>
    </collision>
    <collision>
      <origin rpy="0 1.57079632679 0" xyz="-0.036 0 -0.315"/>
      <geometry>
        <cylinder length="0.013" radius="0.017"/>
      </geometry>
    </collision>
    <inertial>
      <mass value="1.851"/>
      <origin rpy="0 0 0" xyz="0.0418 0 -0.0517"/>
      <inertia ixx="0.0238" ixy="0" ixz="0" iyy="0.0252" iyz="0" izz="0.0044"/>
    </inertial>
  </link>
  <!-- pitch joint connects hip to upper leg -->
  <joint name="front_right_pitch_joint" type="revolute">
    <axis rpy="0 0 0" xyz="1 0 0"/>
    <parent link="front_right_hip"/>
    <child link="front_right_upperleg"/>
    <origin rpy="0 0 0" xyz="0.09875 0 0"/>
    <limit effort="60" lower="-3.14159265359" upper="1.57079632679" velocity="6.0"/>
  </joint>
  <link name="front_right_lowerleg">
    <visual>
      <origin rpy="-1.57079632679 0 0" xyz="0 0 0"/>
      <geometry>
        <mesh filename="package://dogbot_description/meshes/LegLower_nofoot.dae" scale="1.0 1.0 1.0"/>
      </geometry>
    </visual>
    <collision>
      <origin rpy="0 1.57079632679 0" xyz="0 0 0"/>
      <geometry>
        <cylinder length="0.033" radius="0.042"/>
      </geometry>
    </collision>
    <collision>
      <origin rpy="0 0 0" xyz="0.024 -0.0375 -0.0055"/>
      <geometry>
        <box size="0.02 0.017 0.065"/>
      </geometry>
    </collision>
    <collision>
      <origin rpy="0 0 0" xyz="-0.024 -0.0375 -0.0055"/>
      <geometry>
        <box size="0.02 0.017 0.065"/>
      </geometry>
    </collision>
    <collision>
      <origin rpy="0 0.04996 0" xyz="0.01575 -0.0375 -0.145"/>
      <geometry>
        <cylinder length="0.29" radius="0.006"/>
      </geometry>
    </collision>
    <collision>
      <origin rpy="0 -0.04996 0" xyz="-0.01575 -0.0375 -0.145"/>
      <geometry>
        <cylinder length="0.29" radius="0.006"/>
      </geometry>
    </collision>
    <inertial>
      <mass value="0.302"/>
      <origin rpy="0 0 0" xyz="0 -0.029 -0.1439"/>
      <inertia ixx="0.00527" ixy="0" ixz="0" iyy="0.00509" iyz="0" izz="0.0008"/>
    </inertial>
  </link>
  <gazebo reference="front_right_lowerleg">
    <mu1 value="2000.0"/>
    <mu2 value="1000.0"/>
    <kp value="1000000"/>
    <kd value="1.0"/>
    <selfCollide value="true"/>
  </gazebo>
  <joint name="front_right_knee_joint" type="revolute">
    <axis rpy="-6.28318530718 0 0" xyz="1 0 0"/>
    <parent link="front_right_upperleg"/>
    <child link="front_right_lowerleg"/>
    <origin rpy="0 0 0" xyz="0 0 -0.315"/>
    <limit effort="60" lower="-0.02" upper="2.61795" velocity="6.0"/>
  </joint>
  <link name="front_right_foot">
    <visual>
      <origin rpy="-1.57079632679 0 0" xyz="0 0 0"/>
      <geometry>
        <mesh filename="package://dogbot_description/meshes/foot.dae" scale="1.0 1.0 1.0"/>
      </geometry>
    </visual>
    <collision>
      <origin rpy="0 0 0" xyz="0 -0.035 -0.3"/>
      <geometry>
        <sphere radius="0.028"/>
      </geometry>
    </collision>
    <inertial>
      <mass value="0.001"/>
      <origin rpy="0 0 0" xyz="0 0 0"/>
      <inertia ixx="1.66666666667e-10" ixy="0.0" ixz="0.0" iyy="1.66666666667e-10" iyz="0.0" izz="1.66666666667e-10"/>
    </inertial>
  </link>
  <joint name="front_right_foot_joint" type="fixed">
    <axis rpy="0 0 0" xyz="0 1 0"/>
    <parent link="front_right_lowerleg"/>
    <child link="front_right_foot"/>
    <origin rpy="0 0 0" xyz="0 0 0"/>
  </joint>
  <gazebo reference="front_right_foot">
    <mu1 value="2000.0"/>
    <mu2 value="1000.0"/>
    <kp value="1000000"/>
    <kd value="1.0"/>
  </gazebo>
  <transmission name="front_right_roll_transmition">
    <type>transmission_interface/SimpleTransmission</type>
    <joint name="front_right_roll_joint">
      <hardwareInterface>hardware_interface/EffortJointInterface</hardwareInterface>
    </joint>
    <actuator name="front_right_roll_motor">
      <hardwareInterface>hardware_interface/EffortJointInterface</hardwareInterface>
      <mechanicalReduction>1</mechanicalReduction>
    </actuator>
  </transmission>
  <transmission name="front_right_pitch_transmition">
    <type>transmission_interface/SimpleTransmission</type>
    <joint name="front_right_pitch_joint">
      <hardwareInterface>hardware_interface/EffortJointInterface</hardwareInterface>
    </joint>
    <actuator name="front_right_pitch_motor">
      <hardwareInterface>hardware_interface/EffortJointInterface</hardwareInterface>
      <mechanicalReduction>1</mechanicalReduction>
    </actuator>
  </transmission>
  <transmission name="front_right_knee_transmition">
    <type>transmission_interface/SimpleTransmission</type>
    <joint name="front_right_knee_joint">
      <hardwareInterface>hardware_interface/EffortJointInterface</hardwareInterface>
    </joint>
    <actuator name="front_right_knee_motor">
      <hardwareInterface>hardware_interface/EffortJointInterface</hardwareInterface>
      <mechanicalReduction>1</mechanicalReduction>
    </actuator>
  </transmission>
  <gazebo>
    <plugin filename="libhector_gazebo_ros_imu.so" name="imu_plugin">
      <alwaysOn>true</alwaysOn>
      <bodyName>body</bodyName>
      <robotNamespace>dogbot</robotNamespace>
      <topicName>imu</topicName>
      <serviceName>imu_service</serviceName>
      <gaussianNoise>0.0</gaussianNoise>
      <updateRate>20.0</updateRate>
    </plugin>
    <plugin filename="libhector_gazebo_ros_gps.so" name="gps_plugin">
      <alwaysOn>true</alwaysOn>
      <bodyName>body</bodyName>
      <robotNamespace>dogbot</robotNamespace>
      <topicName>gps</topicName>
      <serviceName>imu_service</serviceName>
      <updateRate>100</updateRate>
      <referenceLatitude>51.5</referenceLatitude>
      <referenceLongitude>0.1278</referenceLongitude>
    </plugin>
  </gazebo>
  <!-- Gazebo plugin for ROS Control -->
  <gazebo>
    <plugin filename="libgazebo_ros_control.so" name="gazebo_ros_control">
      <robotNamespace>/dogbot</robotNamespace>
    </plugin>
  </gazebo>
</robot>

